Workbook
Name Coating_Databas: Estimate!#REF!

Sheet Estimate
B1: Today's Date: | F1: Bill To Address:
B2: Job Name: | F2: City, State, Zip:
B3: Job Type: | F3: Contact:
B4: Site Address: | F4: Email Address:
B5: City, State, Zip: | F5: Phone:
B6: Contact: | F6: Fax:
B7: Title:
B8: Email Address:
B9: Phone: | F9: Estimator
A11: Est. Square Feet:
A12: Materials | D12: ='Sq Ft Calculation'!F15 -> 0
A13: *
B14: Type | C14: Sq. Ft. | E14: Unit Price | G14: Est. Units | H14: Est. Cost
A16: Foam | B16: Mfg: | C16: Gaco = 1, NCFI = 2, AccuFoam = 3, OTHER = 4
B17: Types: | C17: 2.0 lb. = 1, 0.5 lb. = 2
D18: Thickness
A19: 11 | B19: =IF(A19=11,"Gaco 2.0 lb.",IF(A19=12,"Gaco 0.5 lb.",IF(A19=21,"NCFI 2.0 lb.",IF(A19=22,"NCFI 0.5 lb.",IF(A19=31,"AccuFoam 2.0 lb.",IF(A19=32,"AccuFoam 0.5 lb.",IF(A19=41,"OTHER 2.0 lb.",IF(A19=42,"OTHER 0.5 lb.")))))))) -> Gaco 2.0 lb. | C19: 0 | D19: 2 | E19: 2.2 | F19: 3500 | G19: =((C19/F19)*D19)*1000 -> 0 | H19: =E19*G19 -> 0
A20: 11 | B20: =IF(A20=11,"Gaco 2.0 lb.",IF(A20=12,"Gaco 0.5 lb.",IF(A20=21,"NCFI 2.0 lb.",IF(A20=22,"NCFI 0.5 lb.",IF(A20=31,"AccuFoam 2.0 lb.",IF(A20=32,"AccuFoam 0.5 lb.",IF(A20=41,"OTHER 2.0 lb.",IF(A20=42,"OTHER 0.5 lb.")))))))) -> Gaco 2.0 lb. | C20: 0 | D20: 2 | E20: 2.2 | F20: 3500 | G20: =((C20/F20)*D20)*1000 -> 0 | H20: =E20*G20 -> 0
A21: 11 | B21: =IF(A21=11,"Gaco 2.0 lb.",IF(A21=12,"Gaco 0.5 lb.",IF(A21=21,"NCFI 2.0 lb.",IF(A21=22,"NCFI 0.5 lb.",IF(A21=31,"AccuFoam 2.0 lb.",IF(A21=32,"AccuFoam 0.5 lb.",IF(A21=41,"OTHER 2.0 lb.",IF(A21=42,"OTHER 0.5 lb.")))))))) -> Gaco 2.0 lb. | C21: 0 | D21: 2 | E21: 2.2 | F21: 3500 | G21: =((C21/F21)*D21)*1000 -> 0 | H21: =E21*G21 -> 0
C23: Linear Ft.
A24: Membrane | C24: 0 | E24: 0.75 | H24: =C24*E24 -> 0
A26: Primer | C26: 0 | E26: 30 | G26: =C26/250 -> 0 | H26: =E26*G26 -> 0
A28: Coating | B28: Types: | C28: DC 315 TB = 1, Acrylic = 2, NoBurn TB = 3
C29: Sq. Ft. | D29: Gal / Sq.
A30: 1 | B30: =IF(A30=1,"DC 315 TB",IF(A30=2,"Acrylic",IF(A30=3,"NoBurn TB",""))) -> DC 315 TB | C30: 0 | D30: 1.5 | E30: 52 | G30: =(((C30/100)*D30))/((100-A$34)/100) -> 0 | H30: =E30*G30 -> 0
A31: 1 | B31: =IF(A31=1,"DC 315 TB",IF(A31=2,"Acrylic",IF(A31=3,"NoBurn TB",""))) -> DC 315 TB | C31: 0 | D31: 1.5 | E31: 52 | G31: =(((C31/100)*D31))/((100-A$34)/100) -> 0 | H31: =E31*G31 -> 0
A32: 1 | B32: =IF(A32=1,"DC 315 TB",IF(A32=2,"Acrylic",IF(A32=3,"NoBurn TB",""))) -> DC 315 TB | C32: 0 | D32: 1.5 | E32: 52 | G32: =(((C32/100)*D32))/((100-A$34)/100) -> 0 | H32: =E32*G32 -> 0
A33: Margin %:
A34: 20
A36: Thinner | B36: Types: | C36: Naphtha VM&P = 1, Mineral Spirits = 2, Xylene= 3
A37: 1 | B37: =IF(A37=1,"Naphtha VM&P",IF(A37=2,"Mineral Spirits",IF(A37=3,"Xylene",""))) -> Naphtha VM&P | E37: 10 | G37: =((G30+G31+G32)/55)*4 -> 0 | H37: =E37*G37 -> 0
A39: Caulk/Sealant | B39: Types: | C39: Can Foam = 1, Liquid Flashing = 2, Pointing Mastic = 3
C40: Linear Ft. | D40: Ft. / Unit
A41: 2 | B41: =IF(A41=1,"Can Foam",IF(A41=2,"Liquid Flashing",IF(A41=3,"Pointing Mastic",""))) -> Liquid Flashing | C41: 0 | D41: 0 | E41: 20 | G41: =IF(D41=0,0,C41/D41) -> 0 | H41: =G41*E41 -> 0
A43: 3 | B43: =IF(A43=1,"Can Foam",IF(A43=2,"Liquid Flashing",IF(A43=3,"Pointing Mastic",""))) -> Pointing Mastic | C43: 0 | D43: 0 | E43: 10 | G43: =IF(D43=0,0,C43/D43) -> 0 | H43: =G43*E43 -> 0
A45: Lift | B45: Types: | C45: Forklift = 1, Boom = 2, Scissor = 3, Articulating = 4
C46: Size | D46: Period | F46: Margin %
A47: 1 | B47: =IF(A47=1,"Forklift",IF(A47=2,"Boom",IF(A47=3,"Scissor",IF(A47=4,"Articulating","")))) -> Forklift | C47: 20' | D47: 0 | E47: 0 | F47: 20 | H47: =D47*E47*(1+(F47/100)) -> 0
A48: 1 | B48: =IF(A48=1,"Forklift",IF(A48=2,"Boom",IF(A48=3,"Scissor",IF(A48=4,"Articulating","")))) -> Forklift | C48: 20' | D48: 0 | E48: 0 | F48: 20 | H48: =D48*E48*(1+(F48/100)) -> 0
A50: Delivery Fee | E50: 0 | G50: 0 | H50: =E50*G50 -> 0
...

Sheet People
E1: Crew Size
A2: Job Classification | B2: Hourly Wage | C2: Burden Rate | D2: 1 | E2: 2 | F2: 3 | G2: 4 | H2: 5 | I2: 6 | J2: 7 | K2: 8
A3: Foreman / Sprayer | B3: 34 | C3: 1.5 | D3: =B3*C3 -> 51 | E3: =B3*C3 -> 51 | F3: =B3*C3 -> 51 | G3: =B3*C3 -> 51 | H3: =B3*C3 -> 51 | I3: =B3*C3 -> 51 | J3: =B3*C3 -> 51 | K3: =B3*C3 -> 51
A4: Sprayer / Trailer | B4: 25 | C4: 1.5 | E4: =B4*C4 -> 37.5 | F4: =B4*C4 -> 37.5 | G4: =B4*C4 -> 37.5 | H4: =B4*C4 -> 37.5 | I4: =B4*C4 -> 37.5 | J4: =B4*C4 -> 37.5 | K4: =B4*C4 -> 37.5
A5: Trailer / Hose | B5: 21.5 | C5: 1.5 | F5: =B5*C5 -> 32.25 | G5: =B5*C5 -> 32.25 | H5: =B5*C5 -> 32.25 | I5: =B5*C5 -> 32.25 | J5: =B5*C5 -> 32.25 | K5: =B5*C5 -> 32.25
A6: Hose / Laborer | B6: 21 | C6: 1.5 | G6: =B6*C6 -> 31.5 | H6: =B6*C6 -> 31.5 | I6: =B6*C6 -> 31.5 | J6: =B6*C6 -> 31.5 | K6: =B6*C6 -> 31.5
A7: Laborer | B7: 20 | C7: 1.5 | H7: =B7*C7 -> 30 | I7: =B7*C7 -> 30 | J7: =B7*C7 -> 30 | K7: =B7*C7 -> 30
A8: Laborer | B8: 20 | C8: 1.5 | I8: =B8*C8 -> 30 | J8: =B8*C8 -> 30 | K8: =B8*C8 -> 30
A9: Laborer | B9: 18 | C9: 1.5 | J9: =B9*C9 -> 27 | K9: =B9*C9 -> 27
A10: Laborer | B10: 18 | C10: 1.5 | K10: =B10*C10 -> 27
A11: Hours /Day | B11: 12
A12: Estimated Cost/Day | D12: =SUM(D3:D10)*B11 -> 612 | E12: =SUM(E3:E10)*B11 -> 1062 | F12: =SUM(F3:F10)*B11 -> 1449 | G12: =SUM(G3:G10)*B11 -> 1827 | H12: =SUM(H3:H10)*B11 -> 2187 | I12: =SUM(I3:I10)*B11 -> 2547 | J12: =SUM(J3:J10)*B11 -> 2871 | K12: =SUM(K3:K10)*B11 -> 3195
A15: Crew Leaders | B15: Hourly | C15: Travel
A16: Mariano Perez | B16: 34 | C16: 20
A17: Gustavo Garcia | B17: 34 | C17: 20
A18: Carlos Garcia | B18: 28 | C18: 20
A19: Abel Reyes | B19: 28 | C19: 20
A20: Santos Ocampo | B20: 27 | C20: 20
A22: Workers | B22: Hourly | C22: Travel
A23: Erik Avila | B23: 25 | C23: 12.5
A24: Miguel Avila | B24: 25 | C24: 10
A25: Juan Loa | B25: 24.5 | C25: 10
A26: Gilberto Morales | B26: 21 | C26: 8.75
A27: Federico | B27: 21 | C27: 7.25
A28: Melvin Lutin | B28: 21.5 | C28: 8
A29: Onilson Morales | B29: 21 | C29: 8
A30: Edvin | B30: 19.5 | C30: 8
A31: Pedro Morales | B31: 20 | C31: 8
A32: Jesus Martinez | B32: 18 | C32: 7.25
A33: Andres | B33: 21.5 | C33: 10.75
A34: Alonso?? | B34: 19 | C34: 7.25

Sheet Job Spec
A1: Job Name | B1: =Estimate!C2 -> 0 | D1: =Estimate!C3 -> 0
A2: Address | B2: =Estimate!C4 -> 0
A3: City, State, ZIP | B3: =Estimate!C5 -> 0 | F3: Estimator | G3: =Estimate!G9 -> 0
A4: Contact Name | B4: =Estimate!C6 -> 0
A5: Cell # | B5: =Estimate!C9 -> 0
A6: Email | B6: =Estimate!C8 -> 0
A7: Mobilizations
A8: Est. # of Days | B8: =Estimate!D103 -> 0
A9: Est. # of Hours | B9: =Estimate!D78+Estimate!D80+Estimate!D82+Estimate!D84+Estimate!D86+Estimate!D88+Estimate!D90+Estimate!D92 -> 0
A10: Est. Crew Size | B10: =Estimate!E97 -> 3 | F10: Total sq. ft. | G10: =Estimate!C12 -> 0
A12: Scope of Work:
A38: Materials Needed | B38: Manufacturer/Product/Color | D38: Quantity | E38: ~ Sq. Ft. | F38: Thickness | G38: Yield.
A39: Foam #1 | B39: =Estimate!B19 -> Gaco 2.0 lb. | D39: =Estimate!G19 -> 0 | E39: =Estimate!C19 -> 0 | F39: =Estimate!D19 -> 2 | G39: =Estimate!F19 -> 3500
A40: Foam #2 | B40: =Estimate!B20 -> Gaco 2.0 lb. | D40: =Estimate!G20 -> 0 | E40: =Estimate!C20 -> 0 | F40: =Estimate!D20 -> 2 | G40: =Estimate!F20 -> 3500
A41: Foam #3 | B41: =Estimate!B21 -> Gaco 2.0 lb. | D41: =Estimate!G21 -> 0 | E41: =Estimate!C21 -> 0 | F41: =Estimate!D21 -> 2 | G41: =Estimate!F21 -> 3500
A42: Coating | B42: =Estimate!B30 -> DC 315 TB | D42: =Estimate!G30 -> 0 | E42: =Estimate!C30 -> 0 | G42: =Estimate!D30 -> 1.5
A44: Other Materials | B44: Manufacturer/Product/Color | D44: Quantity
A45: Can Foam
A46: Plastic + Tape | D46: =(Estimate!C12)/2000 -> 0
A47: Card Board
A48: Vapor Barrior
A49: Iso/Backer Board
A51: Notes: | B51: =Estimate!A126 -> Additional Amount w/o Markup
B52: =Estimate!A127 -> Additional Amount w/o Markup
B53: =Estimate!A128 -> Additional Amount w/o Markup
B54: =Estimate!A129 -> Additional Amount w/o Markup

Sheet Tracking
A1: Actual Amounts
A2: ='Job Spec'!B1 -> 0 | B2: Labor Hours | C2: Travel Hours | D2: Load Hours | E2: OS Hours | F2: Mileage | G2: OS Mileage | H2: Foam Strokes | I2: Thickness (in.) | J2: Sq. Ft. (Foam) | K2: Foam Yield | L2: A-Side Lot # | M2: B-Side Lot # | N2: Coating | O2: Sq. Ft. (Base) | P2: Gal/Sq. (Base) | Q2: Crew | R2: Notes
K16: =IF(OR(H16=0,I16=0,J16=0),"",J16/(H16/1.6)*I16*1000) | P16: =IF(OR(N16=0,O16=0),"",N16/(O16/100)/1.2)
K17: =IF(OR(H17=0,I17=0,J17=0),"",J17/(H17/1.6)*I17*1000) | P17: =IF(OR(N17=0,O17=0),"",N17/(O17/100)/1.2)
K18: =IF(OR(H18=0,I18=0,J18=0),"",J18/(H18/1.6)*I18*1000) | P18: =IF(OR(N18=0,O18=0),"",N18/(O18/100)/1.2)
A19: Insert Additional Lines Here
E20: =SUM(E3:E19) -> 0 | H20: =SUM(H3:H19) -> 0
A21: Daily Totals | B21: =SUM(B3:B19) -> 0 | C21: =SUM(C3:C19) -> 0 | D21: =SUM(D3:D19) -> 0 | E21: =E20*25 -> 0 | F21: =SUM(F3:F19) -> 0 | G21: =SUM(G3:G19) -> 0 | H21: =H20/1.6 -> 0 | I21: =AVERAGE(I3:I19) -> #DIV/0! | J21: =SUM(J3:J19) -> 0 | K21: =AVERAGE(K3:K19) -> #DIV/0! | N21: =SUM(N3:N19) -> 0 | O21: =SUM(O3:O19) -> 0 | P21: =AVERAGE(P3:P19) -> #DIV/0!
A23: Estimated Amounts
B24: =B2 -> Labor Hours | C24: =C2 -> Travel Hours | D24: =D2 -> Load Hours | E24: Overhead | F24: =F2 -> Mileage | G24: =G2 -> OS Mileage | H24: Foam (lbs.) | I24: =I2 -> Thickness (in.) | J24: =J2 -> Sq. Ft. (Foam) | K24: Foam Yield | N24: =N2 -> Coating | O24: =O2 -> Sq. Ft. (Base) | P24: =P2 -> Gal/Sq. (Base)
B25: =SUM(Estimate!D78:D92) -> 0 | C25: =Estimate!E97*Estimate!C97*Estimate!B70 -> 0 | D25: =Estimate!E95*Estimate!C95*Estimate!B70 -> 0 | E25: =Estimate!H118 -> 0 | F25: =Estimate!B70*Estimate!C70 -> 0 | G25: =Estimate!B68*Estimate!C68 -> 0 | H25: =SUM(Estimate!G19:G21) -> 0 | J25: =SUM(Estimate!C19:C21) -> 0 | N25: =SUM(Estimate!G30:G32) -> 0 | O25: =SUM(Estimate!C30:C32) -> 0
A26: Over/Under
B27: =B2 -> Labor Hours | C27: =C2 -> Travel Hours | D27: =D2 -> Load Hours | E27: Overhead | F27: =F2 -> Mileage | G27: =G2 -> OS Mileage | H27: =H24 -> Foam (lbs.) | I27: =I2 -> Thickness (in.) | J27: =J2 -> Sq. Ft. (Foam) | K27: Foam Yield | N27: =N2 -> Coating | O27: =O2 -> Sq. Ft. (Base) | P27: =P2 -> Gal/Sq. (Base)
B28: =B25-B21 -> 0 | C28: =C25-C21 -> 0 | D28: =D25-D21 -> 0 | E28: =E25-E21 -> 0 | F28: =F25-F21 -> 0 | G28: =G25-G21 -> 0 | H28: =H25-H21 -> 0 | I28: =I25-I21 -> #DIV/0! | J28: =J25-J21 -> 0 | K28: =K21-K25 -> #DIV/0! | N28: =N25-N21 -> 0 | O28: =O25-O21 -> 0 | P28: =P25-P21 -> #DIV/0!
B29: =B21/B25 -> #DIV/0! | C29: =C21/C25 -> #DIV/0! | D29: =D21/D25 -> #DIV/0! | E29: =E21/E25 -> #DIV/0! | F29: =F21/F25 -> #DIV/0! | G29: =G21/G25 -> #DIV/0! | H29: =H21/H25 -> #DIV/0! | J29: =J21/J25 -> #DIV/0! | N29: =N21/N25 -> #DIV/0! | O29: =O21/O25 -> #DIV/0!

Sheet Extras
A1: Date | B1: Crew Leader | C1: Description/Notes | D1: Additional Materials Used? | E1: Notified All Parties? | F1: Change Order? | G1: Associated Cost (+/-)
E2: FALSE | F2: FALSE
E3: FALSE | F3: FALSE
E4: FALSE | F4: FALSE
E5: FALSE | F5: FALSE
E6: FALSE | F6: FALSE
E7: FALSE | F7: FALSE
E8: FALSE | F8: FALSE
E9: FALSE | F9: FALSE
E10: FALSE | F10: FALSE
E11: FALSE | F11: FALSE
E12: FALSE | F12: FALSE
E13: FALSE | F13: FALSE
... E201: FALSE | F201: FALSE

Sheet Materials
A1: Solvents | C1: Cost | D1: Unit | E1: Per Gal
A2: VM&P Natha | C2: 190 | D2: 55 | E2: =C2/D2 -> 3.4545455
A3: Xylene | C3: 260 | D3: 55 | E3: =C3/D3 -> 4.7272727
A5: Fabric | B5: Width | C5: Cost | D5: Unit
B6: 4" | C6: 27 | D6: 300
B7: 6" | C7: 37 | D7: 300
B8: 9" | C8: 44 | D8: 300
B9: 12" | C9: 54 | D9: 300
B10: 18" | C10: 80 | D10: 300
B11: 36" | C11: 120 | D11: 300
B12: 48" | C12: 150 | D12: 300
A14: Membrane | B14: Thickness | C14: Cost | D14: Unit
B15: 6" | C15: 22 | D15: 75
B16: 12" | C16: 42 | D16: 75
B17: 18" | C17: 62 | D17: 75
B18: 38.5" | C18: 124 | D18: 75

Sheet Sq Ft Calculation
B2: Description | C2: Height | D2: Width | E2: Total
B4: Wall | E4: =C4*D4 -> 0
E5: =C5*D5 -> 0
E6: =C6*D6 -> 0
E7: =C7*D7 -> 0
E8: =C8*D8 -> 0
B9: Ceiling | E9: =C9*D9 -> 0
E10: =C10*D10 -> 0
E11: =C11*D11 -> 0
E12: =C12*D12 -> 0
B13: Gables | E13: =(C13/2)*D13 -> 0
E14: =(C14/2)*D14 -> 0
E15: =C15*D15 -> 0 | F15: =SUM(E4:E15) -> 0
