Workbook

Sheet General Estimate
H1: BILLABLE
E2: PROJECT NAME:
E3: Address:
E4: Contact Name:
E5: Contact Phone:
E6: Contact Email:
E7: Estimator:
A8: WORK REQUESTED:
A9: Days | C9: Purchase Order #: | F9: Date of Repairs:
B10: Materials | G10: Price | I10: Total
B11: Silicone Coating | G11: 60 | H11: per gal | I11: =A11*G11 -> 0
B12: Reinforced Silicone Coating | G12: 45 | H12: per gal | I12: =A12*G12 -> 0
B13: Caulk | C13: 16 Bronze & Rest is DOW | G13: 16 | H13: each | I13: =A13*G13 -> 0
B14: Caulk | C14: ALDO | D14: Emergency Sealant | G14: 28.5 | H14: each | I14: =A14*G14 -> 0
B15: Granules | G15: 50 | H15: per bucket | I15: =A15*G15 -> 0
B16: Fabric | G16: 1 | H16: per ft. | I16: =A16*G16 -> 0
B17: Brushes/Rollers | D17: brushes | F17: rollers | G17: 5 | H17: each | I17: =A17*G17 -> 0
B18: Solvent | D18: Type | G18: 7 | H18: each | I18: =A18*G18 -> 0
B19: Fasteners | D19: Type | G19: 1 | H19: each | I19: =A19*G19 -> 0
B20: Misc. Materials (Siloxane, Downspout, Etc.) | G20: 250 | H20: per pc | I20: =A20*G20 -> 0
B21: Boots | G21: 42 | H21: per | I21: =A21*G21 -> 0
B22: Mileage | D22: *Charge more for TOLL BRIDGES | G22: 1.25 | H22: each | I22: =A22*G22 -> 0
A23: Labor | B23: Onsite Hours: | E23: Travel: | G23: Hourly Rate | I23: Total
B24: Technician #1 | G24: 50 | H24: per Hr | I24: =A24*G24 -> 0
B25: Technician #2 | G25: 50 | H25: per Hr | I25: =A25*G25 -> 0
B26: Estimate Hrs. (Wes/AP) | G26: 50 | H26: per Hr | I26: =A26*G26 -> 0
B27: Technician #4 | G27: 35 | H27: per Hr | I27: =A27*G27 -> 0
A28: Tech Notes:
A29: Please write as if the customer would see these notes; we can make minor changes as needed. | G29: Total Labor: | I29: =SUM(I24:J28) -> 0
G30: Total Materials: | I30: =SUM(I11:J23) -> 0
G31: Tax : | I31: =I30*6% -> 0
G32: Total Job Cost: | I32: =I29+I30+I31 -> 0
G33: Estimated OH: | I33: =I32*40% -> 0
G34: Final Repair Cost: | I34: =I32+I33 -> 0
G35: APPROVED: | I35: Check here
A36: Billing Information (if different than Site Address)
A37: Name: | E37: Invoice Notes:
A38: Company:
A39: Address:
A40: Phone:
...

Sheet Job Spec
A1: Job Name | B1: ='General Estimate'!G2 -> 0 | I1: To insert a new line (line break) inside an Excel cell, press Alt + Enter on Windows
A2: Address | B2: ='General Estimate'!G3 -> 0 | I2: To create a bulleted list in an Excel cell, double-click the cell, press Alt + 7 (or Alt + 0149 on the numeric keypad) to insert a bullet, type your text, and press Alt + Enter to start a new line.
A3: Contact Name | B3: ='General Estimate'!G4 -> 0 | F3: Estimator | G3: ='General Estimate'!G7 -> 0
A4: Cell # | B4: ='General Estimate'!G5 -> 0
A5: Email | B5: ='General Estimate'!G6 -> 0
A6: Est. # of Days | B6: ='General Estimate'!B9 -> 0
A7: Total # of Hours | B7: =SUM('General Estimate'!A24:A27) -> 0
A8: Est. Crew Size | B8: =SUM('General Estimate'!A24:A27)/('General Estimate'!D23+'General Estimate'!F23)/'General Estimate'!B9 -> #DIV/0! | F8: Total sq. ft.
A10: Scope of Work:
A11: • Set-up jobsite safety (warning lines, barricades around equipment/dumpsters, roof anchors for tie-off around edges, signs, cones, etc.).
A30: Materials Needed | B30: Manufacturer/Product/Color
A31: Silicone Coating | B31: ='General Estimate'!A11 -> 0 | E31: Type/Color:
A32: SF | B32: ='General Estimate'!A12 -> 0
A33: Caulk - Dow | B33: ='General Estimate'!A13 -> 0
A34: Caulk - Aldo | B34: ='General Estimate'!A14 -> 0
A35: Granules | B35: ='General Estimate'!A15 -> 0
A36: Fabric | B36: ='General Estimate'!A16 -> 0
A37: Brushes/Rollers | B37: ='General Estimate'!A17 -> 0
A38: Solvent | B38: ='General Estimate'!A18 -> 0
A39: Fasteners | B39: ='General Estimate'!A19 -> 0
A40: Misc | B40: ='General Estimate'!A20 -> 0
A41: Boots | B41: ='General Estimate'!A21 -> 0
A43: Tech #1 Onsite | B43: ='General Estimate'!A24-('General Estimate'!F23*'General Estimate'!B9) -> 0
A44: Tech #2 Onsite | B44: ='General Estimate'!A25-('General Estimate'!F23*'General Estimate'!B9) -> 0
A45: Tech #3 Onsite | B45: ='General Estimate'!A26-('General Estimate'!F23*'General Estimate'!B9) -> 0
A47: Tech #1 Travel | B47: ='General Estimate'!A24-('General Estimate'!D23*'General Estimate'!B9) -> 0
A48: Tech #2 Travel | B48: ='General Estimate'!A25-('General Estimate'!D23*'General Estimate'!B9) -> 0
A49: Tech #3 Travel | B49: ='General Estimate'!A26-('General Estimate'!D23*'General Estimate'!B9) -> 0
A51: Notes

Sheet Tracking
A1: Actual Amounts
A2: ='General Estimate'!G2 -> 0 | B2: Labor Hours | C2: Travel Hours | D2: Load Hours | E2: OS Hours | F2: Mileage | G2: OS Mileage | H2: Top Coat | I2: Fasteners | J2: Brushes | K2: Fabric | L2: Dow Caulk | M2: Aldo Caulk | N2: Granules | O2: Solvent | P2: SF | Q2: ='General Estimate'!B20 -> Misc. Materials (Siloxane, Downspout, Etc.) | R2: Crew | S2: Notes
A18: Insert Additional Lines Here
E19: =SUM(E2:E17) -> 0
A20: Daily Totals | B20: =SUM(B3:B17) -> 0 | C20: =SUM(C3:C17) -> 0 | D20: =SUM(D3:D17) -> 0 | E20: =E19*25 -> 0 | F20: =SUM(F3:F17) -> 0 | G20: =SUM(G3:G17) -> 0 | H20: =SUM(H3:H17) -> 0 | I20: =SUM(I3:I17) -> 0 | J20: =SUM(J3:J17) -> 0 | K20: =SUM(K3:K17) -> 0 | L20: =SUM(L3:L17) -> 0 | M20: =SUM(M3:M17) -> 0 | ... Q20: =SUM(Q3:Q17) -> 0
A22: Estimated Amounts
B23: =B2 -> Labor Hours | C23: =C2 -> Travel Hours | D23: =D2 -> Load Hours | E23: =E2 -> OS Hours | F23: =F2 -> Mileage | G23: =G2 -> OS Mileage | H23: =H2 -> Top Coat | I23: =I2 -> Fasteners | ... Q23: =Q2 -> Misc. Materials (Siloxane, Downspout, Etc.)
B24: =SUM('Job Spec'!B43:H45) -> 0 | C24: =SUM('Job Spec'!B47:H49) -> 0 | E24: ='General Estimate'!I33 -> 0 | F24: ='General Estimate'!A22 -> 0 | H24: ='General Estimate'!A11 -> 0 | I24: ='General Estimate'!A19 -> 0 | J24: ='General Estimate'!A17 -> 0 | K24: ='General Estimate'!A16 -> 0 | L24: ='General Estimate'!A13 -> 0 | M24: ='General Estimate'!A14 -> 0 | N24: ='General Estimate'!A15 -> 0 | O24: ='General Estimate'!A18 -> 0 | P24: ='General Estimate'!A12 -> 0 | Q24: ='General Estimate'!A20 -> 0
A25: Over/Under
B26: =B2 -> Labor Hours | C26: =C2 -> Travel Hours | D26: =D2 -> Load Hours | E26: =E2 -> OS Hours | F26: =F2 -> Mileage | G26: =G2 -> OS Mileage | H26: =H2 -> Top Coat | I26: =I2 -> Fasteners | ... Q26: =Q2 -> Misc. Materials (Siloxane, Downspout, Etc.)
B27: =B24-B20 -> 0 | C27: =C24-C20 -> 0 | D27: =D24-D20 -> 0 | E27: =E24-E20 -> 0 | F27: =F24-F20 -> 0 | G27: =G24-G20 -> 0 | H27: =H24-H20 -> 0 | I27: =I24-I20 -> 0 | ... Q27: =Q24-Q20 -> 0
B28: =B20/B24 -> #DIV/0! | C28: =C20/C24 -> #DIV/0! | D28: =D20/D24 -> #DIV/0! | E28: =E20/E24 -> #DIV/0! | F28: =F20/F24 -> #DIV/0! | G28: =G20/G24 -> #DIV/0! | H28: =H20/H24 -> #DIV/0! | I28: =I20/I24 -> #DIV/0! | ... Q28: =Q20/Q24 -> #DIV/0!
