Workbook
Name Coating_Databas: Estimate!#REF!

Sheet Estimate
B1: Today's Date: | F1: Bill To Address: | K1: **EDIT HIGHLIGHTED SECTIONS ONLY**
B2: Job Name: | F2: City, State, Zip:
B3: Job Type: | F3: Contact:
B4: Site Address: | F4: Email Address:
B5: City, State, Zip: | F5: Phone:
B6: Contact: | F6: Core Sample
B7: Title: | F7: Structural Deck
B8: Email Address: | F8: Existing Substrate
B9: Phone: | F9: Sales/Estimator
A11: Est. Square Feet: | D11: 1.1 | E11: 1.2 | F11: 1.3
A12: Materials | D12: =C12*D11 -> 0 | E12: =C12*E11 -> 0 | F12: =C12*F11 -> 0
A13: *
B14: Type | C14: Sq. Ft. | E14: Unit Price | G14: Est. Units | H14: Est. Cost
A16: Foam | B16: Mfg: | C16: Gaco = 1, NCFI = 2
B17: Types: | C17: Roof 2.7 = 1
D18: Thickness | F18: Yield
A19: 11 | B19: =IF(A19=11,"Gaco Roof 2.7",IF(A19=21,"NCFI Roof 2.7","")) -> Gaco Roof 2.7 | C19: 0 | D19: 1.5 | E19: 2.15 | F19: 2600 | G19: =((C19/F19)*D19)*1000 -> 0 | H19: =E19*G19 -> 0
A20: 11 | B20: =IF(A20=11,"Gaco Roof 2.7",IF(A20=21,"NCFI Roof 2.7","")) -> Gaco Roof 2.7 | C20: 0 | D20: 1.25 | E20: 2.15 | F20: 2700 | G20: =((C20/F20)*D20)*1000 -> 0 | H20: =E20*G20 -> 0
A21: 11 | B21: =IF(A21=11,"Gaco Roof 2.7",IF(A21=21,"NCFI Roof 2.7","")) -> Gaco Roof 2.7 | C21: 0 | D21: 1.25 | E21: 2.15 | F21: 2700 | G21: =((C21/F21)*D21)*1000 -> 0 | H21: =E21*G21 -> 0
A23: Coating | B23: Mfg: | C23: Gaco = 1, GAF = 2, SW = 3
B24: Types: | C24: Silicone = 1, Acrylic = 2, Urethane = 3, Aluminum = 4
D25: Gal/Sq.
A26: 11 | B26: =IF(A28=11,"Gaco Silicone",IF(A28=12,"Gaco Acrylic",IF(A28=13,"Gaco Urethane",IF(A28=21,"GAF Silicone",IF(A28=22,"GAF Acrylic",IF(A28=23,"GAF Urethane",IF(A28=4,"Aluminum",IF(A28=31,"SW Silicone",IF(A28=32,"SW Acrylic",IF(A28=33,"SW Urethane","")))))))))) -> Gaco Silicone | C26: 0 | D26: 1 | E26: 26 | G26: =(((C26/100)*D26))*(1+($A$30/100)) -> 0 | H26: =E26*G26 -> 0
A27: 11 | B27: =IF(A28=11,"Gaco Silicone",IF(A28=12,"Gaco Acrylic",IF(A28=13,"Gaco Urethane",IF(A28=21,"GAF Silicone",IF(A28=22,"GAF Acrylic",IF(A28=23,"GAF Urethane",IF(A28=4,"Aluminum",IF(A28=31,"SW Silicone",IF(A28=32,"SW Acrylic",IF(A28=33,"SW Urethane","")))))))))) -> Gaco Silicone | C27: 0 | D27: 1 | E27: 26 | G27: =(((C27/100)*D27))*(1+($A$30*0.01)) -> 0 | H27: =E27*G27 -> 0
A28: 11 | B28: =IF(A28=11,"Gaco Silicone",IF(A28=12,"Gaco Acrylic",IF(A28=13,"Gaco Urethane",IF(A28=21,"GAF Silicone",IF(A28=22,"GAF Acrylic",IF(A28=23,"GAF Urethane",IF(A28=4,"Aluminum",IF(A28=31,"SW Silicone",IF(A28=32,"SW Acrylic",IF(A28=33,"SW Urethane","")))))))))) -> Gaco Silicone | C28: 0 | D28: 1 | E28: 36 | G28: =(((C28/100)*D28))*(1+($A$30*0.01)) -> 0 | H28: =E28*G28 -> 0
A29: Margin %
A30: 30
A32: Thinner | B32: Types: | C32: Naphtha VM&P = 1, Mineral Spirits = 2, Xylene= 3
A33: 1 | B33: =IF(A33=1,"Naphtha VM&P",IF(A33=2,"Mineral Spirits",IF(A33=3,"Xylene",""))) -> Naphtha VM&P | E33: 10 | G33: =((G26+G27+G28)/55)*4 -> 0 | H33: =E33*G33 -> 0
A35: Granules | B35: Types: | C35: 3M = 1, SESCO = 2
A36: 1 | B36: =IF(A36=1,"3M",IF(A36=2,"SESCO","")) -> 3M | E36: 26 | G36: =(((C36/100)*50)/100) -> 0 | H36: =E36*G36 -> 0
A38: Primer | B38: Types: | C38: Gaco E-5320 = 1, Red Zinc Oxide = 2, Black Foam = 3
A39: 1 | B39: =IF(A39=1,"Gaco E-5320",IF(A39=2,"Red Zinc Oxide",IF(A39=3,"Black Foam",""))) -> Gaco E-5320 | E39: 40 | G39: =SUM(C39/250) -> 0 | H39: =E39*G39 -> 0
A41: Caulk/Sealant | B41: Types: | C41: Silicone Tube = 1, Silicone Sausage = 2, Urethane Tube = 3
C42: Urethane Sausage = 4, Gaco SF-2000 = 5, Buttergrade = 6
A43: 2 | B43: =IF(A43=1,"Silicone Tube",IF(A43=2,"Silicone Sausage",IF(A43=3,"Urethane Tube",IF(A43=4,"Urethane Sausage",IF(A43=5,"Gaco SF-2000",IF(A43=6,"Buttergrade","")))))) -> Silicone Sausage | E43: 11.5 | H43: =E43*G43 -> 0
A45: 5 | B45: =IF(A45=1,"Silicone Tube",IF(A45=2,"Silicone Sausage",IF(A45=3,"Urethane Tube",IF(A45=4,"Urethane Sausage",IF(A45=5,"Gaco SF-2000",IF(A45=6,"Buttergrade","")))))) -> Gaco SF-2000 | E45: 35 | H45: =E45*G45 -> 0
C46: Linear Ft.
A47: Misc./Seams | C47: 0
D48: Units
...

Sheet People
E1: Crew Size
A2: Job Classification | B2: Hourly Wage | C2: Burden Rate | D2: 1 | E2: 2 | F2: 3 | G2: 4 | H2: 5 | I2: 6 | J2: 7 | K2: 8
A3: Foreman / Sprayer | B3: 34 | C3: 1.5 | D3: =B3*C3 -> 51 | E3: =B3*C3 -> 51 | F3: =B3*C3 -> 51 | G3: =B3*C3 -> 51 | H3: =B3*C3 -> 51 | I3: =B3*C3 -> 51 | J3: =B3*C3 -> 51 | K3: =B3*C3 -> 51
A4: Sprayer / Trailer | B4: 25 | C4: 1.5 | E4: =B4*C4 -> 37.5 | F4: =B4*C4 -> 37.5 | G4: =B4*C4 -> 37.5 | H4: =B4*C4 -> 37.5 | I4: =B4*C4 -> 37.5 | J4: =B4*C4 -> 37.5 | K4: =B4*C4 -> 37.5
A5: Trailer / Hose | B5: 25 | C5: 1.5 | F5: =B5*C5 -> 37.5 | G5: =B5*C5 -> 37.5 | H5: =B5*C5 -> 37.5 | I5: =B5*C5 -> 37.5 | J5: =B5*C5 -> 37.5 | K5: =B5*C5 -> 37.5
A6: Hose / Laborer | B6: 21 | C6: 1.5 | G6: =B6*C6 -> 31.5 | H6: =B6*C6 -> 31.5 | I6: =B6*C6 -> 31.5 | J6: =B6*C6 -> 31.5 | K6: =B6*C6 -> 31.5
A7: Laborer | B7: 21 | C7: 1.5 | H7: =B7*C7 -> 31.5 | I7: =B7*C7 -> 31.5 | J7: =B7*C7 -> 31.5 | K7: =B7*C7 -> 31.5
A8: Laborer | B8: 20 | C8: 1.5 | I8: =B8*C8 -> 30 | J8: =B8*C8 -> 30 | K8: =B8*C8 -> 30
A9: Laborer | B9: 19 | C9: 1.5 | J9: =B9*C9 -> 28.5 | K9: =B9*C9 -> 28.5
A10: Laborer | B10: 18 | C10: 1.5 | K10: =B10*C10 -> 27
A11: Hours /Day | B11: 12
A12: Estimated Cost/Day | D12: =SUM(D3:D10)*B11 -> 612 | E12: =SUM(E3:E10)*B11 -> 1062 | F12: =SUM(F3:F10)*B11 -> 1512 | G12: =SUM(G3:G10)*B11 -> 1890 | H12: =SUM(H3:H10)*B11 -> 2268 | I12: =SUM(I3:I10)*B11 -> 2628 | J12: =SUM(J3:J10)*B11 -> 2970 | K12: =SUM(K3:K10)*B11 -> 3294
A15: Crew Leaders | B15: Hourly | C15: Travel
A16: Mariano Perez | B16: 34 | C16: 20
A17: Gustavo Garcia | B17: 34 | C17: 20
A18: Carlos Garcia | B18: 28 | C18: 20
A19: Abel Reyes | B19: 28 | C19: 20
A20: Santos Ocampo | B20: 27 | C20: 20
A22: Workers | B22: Hourly | C22: Travel
A23: Erik Avila | B23: 25 | C23: 12.5
A24: Miguel Avila | B24: 25 | C24: 10
A25: Juan Loa | B25: 24.5 | C25: 10
A26: Gilberto Morales | B26: 21 | C26: 8.75
A27: Federico | B27: 21 | C27: 7.25
A28: Melvin Lutin | B28: 21.5 | C28: 8
A29: Onilson Morales | B29: 21 | C29: 8
A30: Edvin | B30: 19.5 | C30: 8
A31: Pedro Morales | B31: 20 | C31: 8
A32: Jesus Martinez | B32: 18 | C32: 7.25
A33: Andres | B33: 21.5 | C33: 10.75
A34: Alonso | B34: 19 | C34: 7.25

Sheet TEST Job Spec
A1: Job Name | B1: =Estimate!C2 -> 0 | E1: =Estimate!C3 -> 0 | I1: To insert a new line (line break) inside an Excel cell, press Alt + Enter on Windows
A2: Address | B2: =Estimate!C4 -> 0 | I2: To create a bulleted list in an Excel cell, double-click the cell, press Alt + 7 (or Alt + 0149 on the numeric keypad) to insert a bullet, type your text, and press Alt + Enter to start a new line.
A3: City, State, ZIP | B3: =Estimate!C5 -> 0 | F3: Estimator | G3: =Estimate!G9 -> 0
A4: Contact Name | B4: =Estimate!C6 -> 0 | F4: Warranty | G4: =IF(Estimate!H154>0, Estimate!C154, "N/A") -> N/A
A5: Cell # | B5: =Estimate!C9 -> 0
A6: Email | B6: =Estimate!C8 -> 0
A7: Mobilizations
A8: Est. # of Days | B8: =Estimate!D148 -> 0
A9: Est. # of Hours | B9: =SUM(Estimate!D116+Estimate!D118+Estimate!D120+Estimate!D122+Estimate!D124+Estimate!D126+Estimate!D128+Estimate!D130+Estimate!D132+Estimate!D134) -> 0
A10: Est. Crew Size | B10: =Estimate!E139 -> 0 | F10: Total sq. ft. | G10: =Estimate!C12 -> 0
A12: Scope of Work:
A13: • Set-up jobsite safety (warning lines, barricades around equipment/dumpsters, roof anchors for tie-off around edges, signs, cones, etc.).
A38: Materials Needed | B38: Manufacturer/Product/Color | D38: Quantity | E38: ~ Sq. Ft. | F38: Inches Thick | G38: Yield.
A39: Roof Foam 1 | B39: =Estimate!B19 -> Gaco Roof 2.7 | D39: =Estimate!G19 -> 0 | E39: =Estimate!C19 -> 0 | F39: =Estimate!D19 -> 1.5 | G39: =Estimate!F19 -> 2600
A40: Roof Foam 2 | B40: =Estimate!B20 -> Gaco Roof 2.7 | D40: =Estimate!G20 -> 0 | E40: =Estimate!C20 -> 0 | F40: =Estimate!D20 -> 1.25 | G40: =Estimate!F20 -> 2700
A41: Roof Foam 3 | B41: =Estimate!B21 -> Gaco Roof 2.7 | D41: =Estimate!G21 -> 0 | E41: =Estimate!C21 -> 0 | F41: =Estimate!D21 -> 1.25 | G41: =Estimate!F21 -> 2700
F42: MILS Thick
A43: Coating 1 | B43: =Estimate!B26 -> Gaco Silicone | D43: =Estimate!G26 -> 0 | E43: =Estimate!C26 -> 0 | G43: =Estimate!D26 -> 1
A44: Coating 2 | B44: =Estimate!B27 -> Gaco Silicone | D44: =Estimate!G27 -> 0 | E44: =Estimate!C27 -> 0 | G44: =Estimate!D27 -> 1
A45: Coating 3 | B45: =Estimate!B28 -> Gaco Silicone | D45: =Estimate!G28 -> 0 | E45: =Estimate!C28 -> 0 | G45: =Estimate!D28 -> 1
A47: Other Materials | B47: Manufacturer/Product/Color | F47: Quantity
A48: Caulk | B48: =Estimate!B43 -> Silicone Sausage | F48: =Estimate!G43 -> 0
A49: SF | B49: =Estimate!B45 -> Gaco SF-2000 | F49: =Estimate!G45 -> 0
A50: Thinner | B50: =Estimate!B33 -> Naphtha VM&P | F50: =Estimate!G33 -> 0
A51: Primer | B51: =Estimate!B39 -> Gaco E-5320 | F51: =Estimate!G39 -> 0
A52: Granules | B52: =Estimate!B36 -> 3M | F52: =Estimate!G36 -> 0
A54: Notes:

Sheet Job Spec
A1: Job Name | B1: =Estimate!C2 -> 0 | D1: =Estimate!C3 -> 0 | I1: To insert a new line (line break) inside an Excel cell, press Alt + Enter on Windows
A2: Address | B2: =Estimate!C4 -> 0 | I2: To create a bulleted list in an Excel cell, double-click the cell, press Alt + 7 (or Alt + 0149 on the numeric keypad) to insert a bullet, type your text, and press Alt + Enter to start a new line.
A3: City, State, ZIP | B3: =Estimate!C5 -> 0 | F3: Estimator | G3: =Estimate!G9 -> 0
A4: Contact Name | B4: =Estimate!C6 -> 0 | F4: Warranty | G4: =IF(Estimate!H154>0, Estimate!C154, "N/A") -> N/A
A5: Cell # | B5: =Estimate!C9 -> 0
A6: Email | B6: =Estimate!C8 -> 0
A7: Mobilizations
A8: Est. # of Days | B8: =Estimate!D148 -> 0
A9: Est. # of Hours | B9: =SUM(Estimate!D116+Estimate!D118+Estimate!D120+Estimate!D122+Estimate!D124+Estimate!D126+Estimate!D128+Estimate!D130+Estimate!D132+Estimate!D134) -> 0
A10: Est. Crew Size | B10: =Estimate!E139 -> 0 | F10: Total sq. ft. | G10: =Estimate!C12 -> 0
A12: Scope of Work:
A13: • Set-up jobsite safety (warning lines, barricades around equipment/dumpsters, roof anchors for tie-off around edges, signs, cones, etc.).
A38: Materials Needed | B38: Manufacturer/Product/Color | D38: Quantity | E38: ~ Sq. Ft. | F38: Thickness | G38: Yield.
A39: Roof Foam | B39: =Estimate!B19 -> Gaco Roof 2.7 | D39: =Estimate!G19+Estimate!G20+Estimate!G21 -> 0 | E39: =Estimate!C19+Estimate!C20+Estimate!C21 -> 0 | G39: =Estimate!F19 -> 2600
A40: Base Coat | B40: =Estimate!B26 -> Gaco Silicone | D40: =Estimate!G26 -> 0 | E40: =Estimate!C26 -> 0 | G40: =Estimate!D26 -> 1
A41: Top Coat | B41: =Estimate!B27 -> Gaco Silicone | D41: =Estimate!G27 -> 0 | E41: =Estimate!C27 -> 0 | G41: =Estimate!D27 -> 1
A43: Other Materials | B43: Manufacturer/Product/Color | F43: Quantity
A44: Caulk | B44: =Estimate!B43 -> Silicone Sausage | F44: =Estimate!G43 -> 0
A45: SF | B45: =Estimate!B45 -> Gaco SF-2000 | F45: =Estimate!G45 -> 0
A46: Thinner | B46: =Estimate!B33 -> Naphtha VM&P | F46: =Estimate!G33 -> 0
A47: Primer | B47: =Estimate!B39 -> Gaco E-5320 | F47: =Estimate!G39 -> 0
A48: Granules | B48: =Estimate!B36 -> 3M | F48: =Estimate!G36 -> 0
A50: Notes:

Sheet Tracking
A1: Actual Amounts
B2: Labor Hours | C2: Travel Hours | D2: Load Hours | E2: OS Hours | F2: Mileage | G2: OS Mileage | H2: Foam Strokes | I2: Thickness (in.) | J2: Sq. Ft. (Foam) | K2: Foam Yield | L2: A-Side Lot # | M2: B-Side Lot # | N2: Base Coat | O2: Sq. Ft. (Base) | P2: Gal/Sq. (Base) | Q2: Top Coat | R2: Sq. Ft. (Top) | S2: Gal/Sq. (Top) | T2: Granules | U2: Caulk | V2: Primer | W2: SF | X2: Crew | Y2: Notes
K3: =IF(OR(H3=0,I3=0,J3=0),"",J3/(H3/1.6)*I3*1000)
K4: =IF(OR(H4=0,I4=0,J4=0),"",J4/(H4/1.6)*I4*1000)
K5: =IF(OR(H5=0,I5=0,J5=0),"",J5/(H5/1.6)*I5*1000)
K6: =IF(OR(H6=0,I6=0,J6=0),"",J6/(H6/1.6)*I6*1000)
K7: =IF(OR(H7=0,I7=0,J7=0),"",J7/(H7/1.6)*I7*1000)
K8: =IF(OR(H8=0,I8=0,J8=0),"",J8/(H8/1.6)*I8*1000)
K9: =IF(OR(H9=0,I9=0,J9=0),"",J9/(H9/1.6)*I9*1000)
K10: =IF(OR(H10=0,I10=0,J10=0),"",J10/(H10/1.6)*I10*1000)
K11: =IF(OR(H11=0,I11=0,J11=0),"",J11/(H11/1.6)*I11*1000)
K12: =IF(OR(H12=0,I12=0,J12=0),"",J12/(H12/1.6)*I12*1000)
K13: =IF(OR(H13=0,I13=0,J13=0),"",J13/(H13/1.6)*I13*1000)
K14: =IF(OR(H14=0,I14=0,J14=0),"",J14/(H14/1.6)*I14*1000)
K15: =IF(OR(H15=0,I15=0,J15=0),"",J15/(H15/1.6)*I15*1000)
K16: =IF(OR(H16=0,I16=0,J16=0),"",J16/(H16/1.6)*I16*1000) | P16: =IF(OR(N16=0,O16=0),"",N16/(O16/100)/1.2) | S16: =IF(OR(Q16=0,R16=0),"",Q16/(R16/100)/1.2)
K17: =IF(OR(H17=0,I17=0,J17=0),"",J17/(H17/1.6)*I17*1000) | P17: =IF(OR(N17=0,O17=0),"",N17/(O17/100)/1.2) | S17: =IF(OR(Q17=0,R17=0),"",Q17/(R17/100)/1.2)
K18: =IF(OR(H18=0,I18=0,J18=0),"",J18/(H18/1.6)*I18*1000) | P18: =IF(OR(N18=0,O18=0),"",N18/(O18/100)/1.2) | S18: =IF(OR(Q18=0,R18=0),"",Q18/(R18/100)/1.2)
A19: Insert Additional Lines Here
E20: =SUM(E3:E19) -> 0 | H20: =SUM(H3:H19) -> 0
A21: Daily Totals | B21: =SUM(B3:B19) -> 0 | C21: =SUM(C3:C19) -> 0 | D21: =SUM(D3:D19) -> 0 | E21: =E20*25 -> 0 | F21: =SUM(F3:F19) -> 0 | G21: =SUM(G3:G19) -> 0 | H21: =H20/1.6 -> 0 | I21: =AVERAGE(I4:I19) -> #DIV/0! | J21: =SUM(J4:J19) -> 0 | K21: =AVERAGE(K4:K19) -> #DIV/0! | N21: =SUM(N3:N19) -> 0 | O21: =SUM(O3:O19) -> 0 | P21: =AVERAGE(P3:P19) -> #DIV/0! | Q21: =SUM(Q3:Q19) -> 0 | R21: =SUM(R3:R19) -> 0 | S21: =AVERAGE(S3:S19) -> #DIV/0! | T21: =SUM(T3:T19) -> 0 | U21: =SUM(U3:U19) -> 0 | V21: =SUM(V3:V19) -> 0 | W21: =SUM(W3:W19) -> 0
A23: Estimated Amounts
B24: =B2 -> Labor Hours | C24: =C2 -> Travel Hours | D24: =D2 -> Load Hours | E24: Overhead | F24: =F2 -> Mileage | G24: =G2 -> OS Mileage | H24: Foam (lbs.) | I24: =I2 -> Thickness (in.) | J24: =J2 -> Sq. Ft. (Foam) | K24: Foam Yield | N24: =N2 -> Base Coat | O24: =O2 -> Sq. Ft. (Base) | P24: =P2 -> Gal/Sq. (Base) | Q24: =Q2 -> Top Coat | R24: =R2 -> Sq. Ft. (Top) | S24: =S2 -> Gal/Sq. (Top) | T24: =T2 -> Granules | U24: =U2 -> Caulk | V24: =V2 -> Primer | W24: SF
B25: =SUM(Estimate!D116:D134) -> 0 | C25: =Estimate!E139*Estimate!C139*Estimate!B108 -> 0 | D25: =Estimate!E137*Estimate!C137*Estimate!B108 -> 0 | E25: =Estimate!H165 -> 0 | F25: =Estimate!B108*Estimate!C108 -> 0 | G25: =Estimate!B106*Estimate!C106 -> 0 | H25: =SUM(Estimate!G19:G21) -> 0 | J25: =SUM(Estimate!C19:C21) -> 0 | N25: =Estimate!G26 -> 0 | O25: =Estimate!C27 -> 0 | P25: =Estimate!D26 -> 1 | Q25: =Estimate!G27 -> 0 | R25: =Estimate!C27 -> 0 | S25: =Estimate!D27 -> 1 | T25: =Estimate!G36 -> 0 | U25: =Estimate!G43 -> 0 | V25: =Estimate!G39 -> 0 | W25: =Estimate!G45 -> 0
A26: Over/Under
B27: =B2 -> Labor Hours | C27: =C2 -> Travel Hours | D27: =D2 -> Load Hours | E27: Overhead | F27: =F2 -> Mileage | G27: =G2 -> OS Mileage | H27: =H24 -> Foam (lbs.) | I27: =I2 -> Thickness (in.) | J27: =J2 -> Sq. Ft. (Foam) | K27: Foam Yield | N27: =N2 -> Base Coat | O27: =O2 -> Sq. Ft. (Base) | P27: =P2 -> Gal/Sq. (Base) | Q27: =Q2 -> Top Coat | R27: =R2 -> Sq. Ft. (Top) | S27: =S2 -> Gal/Sq. (Top) | T27: =T2 -> Granules | U27: =U2 -> Caulk | ... W27: =W2 -> SF
B28: =B25-B21 -> 0 | C28: =C25-C21 -> 0 | D28: =D25-D21 -> 0 | E28: =E25-E21 -> 0 | F28: =F25-F21 -> 0 | G28: =G25-G21 -> 0 | H28: =H25-H21 -> 0 | I28: =I25-I21 -> #DIV/0! | J28: =J25-J21 -> 0 | K28: =K21-K25 -> #DIV/0! | N28: =N25-N21 -> 0 | O28: =O25-O21 -> 0 | P28: =P25-P21 -> #DIV/0! | Q28: =Q25-Q21 -> 0 | R28: =R25-R21 -> 0 | S28: =S25-S21 -> #DIV/0! | T28: =T25-T21 -> 0 | U28: =U25-U21 -> 0 | ... W28: =W25-W21 -> 0
B29: =B21/B25 -> #DIV/0! | C29: =C21/C25 -> #DIV/0! | D29: =D21/D25 -> #DIV/0! | E29: =E21/E25 -> #DIV/0! | F29: =F21/F25 -> #DIV/0! | G29: =G21/G25 -> #DIV/0! | H29: =H21/H25 -> #DIV/0! | J29: =J21/J25 -> #DIV/0! | N29: =N21/N25 -> #DIV/0! | O29: =O21/O25 -> #DIV/0! | Q29: =Q21/Q25 -> #DIV/0! | R29: =R21/R25 -> #DIV/0! | T29: =T21/T25 -> #DIV/0! | U29: =U21/U25 -> #DIV/0! | V29: =V21/V25 -> #DIV/0! | W29: =W21/W25 -> #DIV/0!

Sheet Extras
A1: Date | B1: Crew Leader | C1: Description/Notes | D1: Additional Materials Used? | E1: Notified All Parties? | F1: Change Order? | G1: Associated Cost (+/-)
E2: FALSE | F2: FALSE
E3: FALSE | F3: FALSE
E4: FALSE | F4: FALSE
E5: FALSE | F5: FALSE
E6: FALSE | F6: FALSE
E7: FALSE | F7: FALSE
E8: FALSE | F8: FALSE
E9: FALSE | F9: FALSE
E10: FALSE | F10: FALSE
E11: FALSE | F11: FALSE
E12: FALSE | F12: FALSE
E13: FALSE | F13: FALSE
... E201: FALSE | F201: FALSE

Sheet Warranty
A2: Building Owner or Representative | F2: =Estimate!C6 -> 0
A3: Building Address | F3: =Estimate!C4 -> 0 | H3: =Estimate!C5 -> 0
A4: Spray-Tec System | F4: =Estimate!C3 -> 0
A5: Warranty Term | F5: =IF(Estimate!G155>0, Estimate!B155, "N/A") -> N/A
A6: Roof Sections Covered
A7: Date of Issue
A8: Date of Expiration
A10: SPRAY-TEC, INC. hereby warrants to the Owner of the building located at the address listed above, subject to the terms, conditions, and limitations set forth below, that the Spray-Tec roof system (listed above) will not leak due to deterioration of the newly-sprayed coating or the application thereof, as the result of ordinary weather conditions, for the warranty period set forth above
A15: THIS WARRANTY IS SUBJECT TO THE FOLLOWING TERMS AND CONDITIONS:
A17: 1. The warranty does not include leaks, damage or failure caused by or due to hail, lightning, windstorm, tornado, fire, earthquake, hurricane, or other unusual phenomena of the elements or Acts of God; settlement, movement, deflection, warpage, distortion, displacement or any other failure of the structure; cracks, breaks or openings in the substrate to which the materials are applied, as well as cracks, breaks, blisters or ruptures in the structural base exceeding 1/16” in width; surface alterations, additions, objects placed or installations made on the finished surface or use of the finished surface for walking or recreational areas or other unnatural or unintended uses; penetration, vandalism damage or attach by third parties and foreign objects or agents, including animal and plant life, failure of flashings, expansion and control joints and metal work and repairs required by reason of defects therein or any manner related to the design and construction of the building; discoloration or change in visual appearance due to accumulation or streaking of dirt or other airborne materials deposited on the surface from the atmosphere.
A29: 2. No claim may be made under this warranty until all payments and other obligations of the contract between the Owner and SPRAY-TEC, INC. have been made and fulfilled by the Owner.
A32: 3. Written notice of any defect or malfunction must be delivered to SPRAY-TEC, INC. within thirty (30) days of discovery of same.
A35: 4. Prior to repair or replacement of any defective materials or installation, it shall be the Owner’s responsibility to remove, at Owner’s expense, all obstructions from the affected area that would hinder repairs being made in the most expeditious and least expensive manner possible.
A39: 5. Owner’s exclusive remedy for claims arising under this warranty shall be repair or replacement, at SPRAY-TEC’s option, during the warranty period. This remedy shall be the sole and exclusive remedy for the obligations of SPRAY-TEC arising from the installation. In no case will SPRAY-TEC be liable for incidental or consequential loss or damage, including, but not limited to property, delay in work, loss of goodwill, loss of profits or other economic loss, whether such incidental or consequential loss or damage is claimed on account of breach of contract, negligence, strict liability, in tort or other legal theory.
A46: 6. On an annual basis, SPRAY-TEC shall have the right, at its option, to inspect or have inspected the roofing system and any other areas it determines necessary and shall, with the Owner’s authorization and at the Owner’s expense, make or cause to be made repairs of any damages which are not the responsibility of SPRAY-TEC. This warranty shall be terminated automatically if SPRAY-TEC is not allowed to perform an inspection and if SPRAY-TEC’s recommendations are not followed.
A52: 7. SPRAY-TEC neither assumes nor authorizes its personnel or any other person to extend any other warranty in connection with the installation of the new foam/ silicone coating roof system.
A55: 8. This warranty constitutes the entire and final expression of this warranty, and it is a complete and conclusive statement of the terms of this warranty.
A58: COVERAGE | D58: CLAIM PROCESS | G58: ITEMS NOT COVERED
A59: Covers defects in workmanship | D59: Submit claim in writing within warranty period Website > Submit Warranty Claim | G59: Normal wear and tear, intentional damage, negligent or deferred maintenance.
A63: Covers labor for repairs | D63: Notify contractor of issue within warranty period | G63: Limited to original repair scope Modifications by unauthorized personnel
A65: Covers materials for repair | D65: Provide evidence of defect with materials | G65: Excludes normal wear and tear Acts of nature
A68: This warranty is null and void should any person or persons not specifically authorized by SPRAY-TEC perform any repairs to the installation. SPRAY-TEC makes no representations or warranties of any kind, express or implied, whether as to merchantability, fitness for a particular purpose, or any other matter, except as specifically set forth on the face hereof with respect to the goods it sells and/or installs.
A73: OWNER | G73: SPRAY-TEC INC.
A74: By: __________________________________ | G74: By: __________________________________
A75: Title: _________________________________ | G75: Title: _________________________________
A76: Date: ________________________________ | G76: Date: ________________________________
A104: Thank you for partnering with our Team on this project! We aim to make you a PROUD Spray-Tec Customer for the life of your roof and beyond! Enclosed you will find your full system warranty. Please read through it carefully. We recommend you take a few minutes to note what your warranty does NOT cover: hail, tornadoes and other Acts of God; mechanical damage from various trades; clogged gutters or roof drains, are not covered in your warranty. To comply with warranty standards, proper maintenance IS required on our systems. Like many things, annual maintenance can extend the life of your roof well beyond it's warranty. Your new roof should be serviced once (preferably twice!) a year. As part of our loyalty program, we will inspect and perform any necessary maintenance/repairs to your roof one time after this warranty is signed. At that time, a member of our Team will contact you to schedule the inspection. Your presence is not required; you will receive an email of our findings when the inspection is finished. Based on the results of this initial visit, you will be offered the opportunity to enroll in an Annual Maintenance program that best fits your roof’s needs. To learn more about our Annual Service Program (STAMP), please visit our website: www.spray-tec.com/repairs/ Thank you again, Haley J. Burge Operations
A139: NEED FURTHER ASSISTANCE?
A140: Please Contact Our Team from the Directory Below:
A142: Website: www.spray-tec.com | D142: Office Phone: (502) 633-5499 | H142: Fax: (502) 633-5499
A144: Department | C144: Spray-Tec Team | E144: Contact Information
A145: Sales/Estimating | C145: Aaron Martin | E145: amartin@spray-tec.com | Office x105 | (502) 321-1008
C146: Anthony Palmer | E146: anthony@spray-tec.com | Office x106 | (502) 743-1085
A147: Repairs & Service | C147: Haley J. Burge | E147: haley@spray-tec.com | Office x101 | (502) 321-6309
A148: Financial | C148: Kay M. Jordan | E148: kay@spray-tec.com | Office x103
A149: Production | C149: Quin Heisler | E149: quin@spray-tec.com | (502) 321-0867

Sheet Materials
A1: Solvents | C1: Cost | D1: Unit | E1: Per Gal
A2: VM&P Natha | C2: 190 | D2: 55 | E2: =C2/D2 -> 3.4545455
A3: Xylene | C3: 260 | D3: 55 | E3: =C3/D3 -> 4.7272727
A5: Fabric | B5: Width | C5: Cost | D5: Unit
B6: 4" | C6: 26.73 | D6: 300
B7: 6" | C7: 37 | D7: 300
B8: 9" | C8: 44 | D8: 300
B9: 12" | C9: 53.03 | D9: 300
B10: 18" | C10: 79.17 | D10: 300
B11: 36" | C11: 120 | D11: 300
B12: 48" | C12: 150 | D12: 300
A14: Board | B14: Thickness | C14: Cost | D14: Truckload | E14: Unit
A15: Dens Deck | B15: 0.25" | C15: 36.5 | E15: Square
A16: Blackboard | B16: .5" | C16: 26.78 | D16: 24.5 | E16: Square
A17: Type X Gyp. Brd | B17: .5" | C17: 30 | D17: 28 | E17: Square
A18: ISO board | B18: 1" | C18: 47.38 | D18: 42.25 | E18: Square
A19: ISO board | B19: 1.5" | C19: 58.11 | D19: 48.33 | E19: Square
A20: ISO board | B20: 2" | C20: 77.47 | D20: 64.5 | E20: Square
A21: ISO board | B21: 3" | C21: 88 | D21: 73 | E21: Square
A24: Fasteners | B24: Length | C24: Cost | D24: Unit
A25: Metal Screws | B25: 3.25 | C25: 90.05 | D25: 1000
B26: 3.75 | C26: 98.47 | D26: 1000
B27: 4.5 | C27: 117.15 | D27: 1000
B28: 5 | C28: 140.37 | D28: 1000
B29: 6 | C29: 172.67 | D29: 1000
B30: 7 | C30: 244.79 | D30: 1000
B31: 8 | C31: 276.01 | D31: 1000
B32: >8 | C32: call for pricing
A34: Plates
A35: Carlisle | C35: 79.05 | D35: 1000
