Workbook
Name Coating_Databas: [1]Estimate!#REF!
Name Coating_Databas: Estimate!#REF!

Sheet Estimate
B1: Today's Date: | C1: 45847 | F1: Bill To Address:
B2: Job Name: | C2: Boone - McCall Residence | F2: City, State, Zip:
B3: Job Type: | C3: Insulation - Walls Only | F3: Contact:
B4: Site Address: | C4: 2333 Todds Point Rd. | F4: Email Address:
B5: City, State, Zip: | C5: Simpsonville, KY | F5: Phone:
B6: Contact: | C6: Dillon Boone | F6: Fax:
B7: Title:
B8: Email Address:
B9: Phone:
A11: Est. Square Feet:
A12: Materials | C12: 2637 | D12: ='Sq Ft Calculation'!F15 -> 0
A13: *
B14: Type | C14: Sq. Ft. | E14: Unit Price | G14: Est. Units | H14: Est. Cost
A16: Foam | B16: Mfg: | C16: Gaco = 1, NCFI = 2, BASF = 3, PSI = 4, Demilec = 5
B17: Types: | C17: 2.0 lb. = 1, 0.5 lb. = 2
D18: Thickness
A19: 11 | B19: =IF(A19=11,"Gaco 2.0 lb.",IF(A19=12,"Gaco 0.5 lb.",IF(A19=21,"NCFI 2.0 lb.",IF(A19=22,"NCFI 0.5 lb.",IF(A19=31,"BASF 2.0 lb.",IF(A19=32,"BASF 0.5 lb.",IF(A19=41,"PSI 2.0 lb.",IF(A19=42,"PSI 0.5 lb.",IF(A19=51,"Demilec 2.0 lb.",IF(A19=52,"Demilec 0.5 lb.","")))))))))) -> Gaco 2.0 lb. | C19: 2800 | D19: 4.25 | E19: 1.63 | F19: 13500 | G19: =((C19/F19)*D19)*1000 -> 881.48148 | H19: =E19*G19 -> 1436.8148
A20: 11 | B20: =IF(A20=11,"Gaco 2.0 lb.",IF(A20=12,"Gaco 0.5 lb.",IF(A20=21,"NCFI 2.0 lb.",IF(A20=22,"NCFI 0.5 lb.",IF(A20=31,"BASF 2.0 lb.",IF(A20=32,"BASF 0.5 lb.",IF(A20=41,"PSI 2.0 lb.",IF(A20=42,"PSI 0.5 lb.",IF(A20=51,"Demilec 2.0 lb.",IF(A20=52,"Demilec 0.5 lb.","")))))))))) -> Gaco 2.0 lb. | C20: 0 | D20: 2 | E20: 2.2 | F20: 3500 | G20: =((C20/F20)*D20)*1000 -> 0 | H20: =E20*G20 -> 0
A21: 11 | B21: =IF(A21=11,"Gaco 2.0 lb.",IF(A21=12,"Gaco 0.5 lb.",IF(A21=21,"NCFI 2.0 lb.",IF(A21=22,"NCFI 0.5 lb.",IF(A21=31,"BASF 2.0 lb.",IF(A21=32,"BASF 0.5 lb.",IF(A21=41,"PSI 2.0 lb.",IF(A21=42,"PSI 0.5 lb.",IF(A21=51,"Demilec 2.0 lb.",IF(A21=52,"Demilec 0.5 lb.","")))))))))) -> Gaco 2.0 lb. | C21: 0 | D21: 2 | E21: 2.2 | F21: 3500 | G21: =((C21/F21)*D21)*1000 -> 0 | H21: =E21*G21 -> 0
C23: Linear Ft.
A24: Membrane | C24: 0 | E24: 0.75 | H24: =C24*E24 -> 0
A26: Primer | C26: 0 | E26: 30 | G26: =C26/250 -> 0 | H26: =E26*G26 -> 0
A28: Coating | B28: Types: | C28: DC 315 TB = 1, Acrylic = 2, NoBurn TB = 3
C29: Sq. Ft. | D29: Gal / Sq.
A30: 1 | B30: =IF(A30=1,"DC 315 TB",IF(A30=2,"Acrylic",IF(A30=3,"NoBurn TB",""))) -> DC 315 TB | C30: 0 | D30: 1.5 | E30: 52 | G30: =(((C30/100)*D30))/((100-A$34)/100) -> 0 | H30: =E30*G30 -> 0
A31: 1 | B31: =IF(A31=1,"DC 315 TB",IF(A31=2,"Acrylic",IF(A31=3,"NoBurn TB",""))) -> DC 315 TB | C31: 0 | D31: 1.5 | E31: 52 | G31: =(((C31/100)*D31))/((100-A$34)/100) -> 0 | H31: =E31*G31 -> 0
A32: 1 | B32: =IF(A32=1,"DC 315 TB",IF(A32=2,"Acrylic",IF(A32=3,"NoBurn TB",""))) -> DC 315 TB | C32: 0 | D32: 1.5 | E32: 52 | G32: =(((C32/100)*D32))/((100-A$34)/100) -> 0 | H32: =E32*G32 -> 0
A33: Margin %:
A34: 20
A36: Thinner | B36: Types: | C36: Naphtha VM&P = 1, Mineral Spirits = 2, Xylene= 3
A37: 1 | B37: =IF(A37=1,"Naphtha VM&P",IF(A37=2,"Mineral Spirits",IF(A37=3,"Xylene",""))) -> Naphtha VM&P | E37: 10 | G37: =((G30+G31+G32)/55)*4 -> 0 | H37: =E37*G37 -> 0
A39: Caulk/Sealant | B39: Types: | C39: Can Foam = 1, Liquid Flashing = 2, Pointing Mastic = 3
C40: Linear Ft. | D40: Ft. / Unit
A41: 2 | B41: =IF(A41=1,"Can Foam",IF(A41=2,"Liquid Flashing",IF(A41=3,"Pointing Mastic",""))) -> Liquid Flashing | C41: 0 | D41: 0 | E41: 20 | G41: =IF(D41=0,0,C41/D41) -> 0 | H41: =G41*E41 -> 0
A43: 3 | B43: =IF(A43=1,"Can Foam",IF(A43=2,"Liquid Flashing",IF(A43=3,"Pointing Mastic",""))) -> Pointing Mastic | C43: 0 | D43: 0 | E43: 10 | G43: =IF(D43=0,0,C43/D43) -> 0 | H43: =G43*E43 -> 0
A45: Lift | B45: Types: | C45: Forklift = 1, Boom = 2, Scissor = 3, Articulating = 4
C46: Size | D46: Period | F46: Margin %
A47: 1 | B47: =IF(A47=1,"Forklift",IF(A47=2,"Boom",IF(A47=3,"Scissor",IF(A47=4,"Articulating","")))) -> Forklift | C47: 20' | D47: 0 | E47: 0 | F47: 20 | H47: =D47*E47*(1+(F47/100)) -> 0
A48: 1 | B48: =IF(A48=1,"Forklift",IF(A48=2,"Boom",IF(A48=3,"Scissor",IF(A48=4,"Articulating","")))) -> Forklift | C48: 20' | D48: 0 | E48: 0 | F48: 20 | H48: =D48*E48*(1+(F48/100)) -> 0
A50: Delivery Fee | E50: 0 | G50: 0 | H50: =E50*G50 -> 0
...

Sheet People
E1: Crew Size
A2: Job Classification | B2: Hourly Wage | C2: Burden Rate | D2: 1 | E2: 2 | F2: 3 | G2: 4 | H2: 5 | I2: 6 | J2: 7 | K2: 8
A3: Foreman / Sprayer | B3: 33 | C3: 1.2 | D3: =B3*C3 -> 39.6 | E3: =B3*C3 -> 39.6 | F3: =B3*C3 -> 39.6 | G3: =B3*C3 -> 39.6 | H3: =B3*C3 -> 39.6 | I3: =B3*C3 -> 39.6 | J3: =B3*C3 -> 39.6 | K3: =B3*C3 -> 39.6
A4: Sprayer / Trailer | B4: 23.5 | C4: 1.2 | E4: =B4*C4 -> 28.2 | F4: =B4*C4 -> 28.2 | G4: =B4*C4 -> 28.2 | H4: =B4*C4 -> 28.2 | I4: =B4*C4 -> 28.2 | J4: =B4*C4 -> 28.2 | K4: =B4*C4 -> 28.2
A5: Trailer / Hose | B5: 21.5 | C5: 1.2 | F5: =B5*C5 -> 25.8 | G5: =B5*C5 -> 25.8 | H5: =B5*C5 -> 25.8 | I5: =B5*C5 -> 25.8 | J5: =B5*C5 -> 25.8 | K5: =B5*C5 -> 25.8
A6: Hose / Laborer | B6: 21 | C6: 1.2 | G6: =B6*C6 -> 25.2 | H6: =B6*C6 -> 25.2 | I6: =B6*C6 -> 25.2 | J6: =B6*C6 -> 25.2 | K6: =B6*C6 -> 25.2
A7: Laborer | B7: 20 | C7: 1.2 | H7: =B7*C7 -> 24 | I7: =B7*C7 -> 24 | J7: =B7*C7 -> 24 | K7: =B7*C7 -> 24
A8: Laborer | B8: 20 | C8: 1.2 | I8: =B8*C8 -> 24 | J8: =B8*C8 -> 24 | K8: =B8*C8 -> 24
A9: Laborer | B9: 18 | C9: 1.2 | J9: =B9*C9 -> 21.6 | K9: =B9*C9 -> 21.6
A10: Laborer | B10: 18 | C10: 1.2 | K10: =B10*C10 -> 21.6
A11: Hours /Day | B11: 10
A12: Estimated Cost/Day | D12: =SUM(D3:D10)*B11 -> 396 | E12: =SUM(E3:E10)*B11 -> 678 | F12: =SUM(F3:F10)*B11 -> 936 | G12: =SUM(G3:G10)*B11 -> 1188 | H12: =SUM(H3:H10)*B11 -> 1428 | I12: =SUM(I3:I10)*B11 -> 1668 | J12: =SUM(J3:J10)*B11 -> 1884 | K12: =SUM(K3:K10)*B11 -> 2100
A15: Crew Leaders | B15: Hourly | C15: Travel
A16: Mariano Perez | B16: 33 | C16: 20
A17: Carlos Garcia | B17: 28 | C17: 20
A18: Abel Reyes | B18: 28 | C18: 20
A19: Miguel Avila | B19: 25 | C19: 10
A21: Workers | B21: Hourly | C21: Travel
A22: Hugo | B22: 28 | C22: 10
A23: Santos | B23: 25 | C23: 20
A24: Erik Avila | B24: 25 | C24: 12.5
A25: Michael | B25: 23.5 | C25: 11.75
A26: Juan Loa | B26: 23 | C26: 10
A27: Axel | B27: 23 | C27: 10
A28: Gilberto Morales | B28: 21 | C28: 8.75
A29: Melvin Lutin | B29: 20 | C29: 8
A30: Ramiro | B30: 20 | C30: 10
A31: Jesus | B31: 20 | C31: 7.25
A32: Onilson Morales | B32: 19.5 | C32: 8
A33: Frederico | B33: 19 | C33: 7.25
A34: Pedro Morales | B34: 18.5 | C34: 8
A37: TEMP Workers | B37: Hourly | C37: Travel
A38: Nelvi | B38: 19 | C38: 7.25
A39: Bryan | B39: 18 | C39: 7.25
A40: Jose | B40: 18 | C40: 7.25
A41: Maura | B41: 18 | C41: 7.25
A42: David | B42: 17 | C42: 7.25
A43: Felipe | B43: 17 | C43: 7.25

Sheet Materials
A1: Solvents | C1: Cost | D1: Unit | E1: Per Gal
A2: VM&P Natha | C2: 190 | D2: 55 | E2: =C2/D2 -> 3.4545455
A3: Xylene | C3: 260 | D3: 55 | E3: =C3/D3 -> 4.7272727
A5: Fabric | B5: Width | C5: Cost | D5: Unit
B6: 4" | C6: 27 | D6: 300
B7: 6" | C7: 37 | D7: 300
B8: 9" | C8: 44 | D8: 300
B9: 12" | C9: 54 | D9: 300
B10: 18" | C10: 80 | D10: 300
B11: 36" | C11: 120 | D11: 300
B12: 48" | C12: 150 | D12: 300
A14: Membrane | B14: Thickness | C14: Cost | D14: Unit
B15: 6" | C15: 22 | D15: 75
B16: 12" | C16: 42 | D16: 75
B17: 18" | C17: 62 | D17: 75
B18: 38.5" | C18: 124 | D18: 75

Sheet General

Sheet Sq Ft Calculation
B2: Description | C2: Height | D2: Width | E2: Total
B4: Wall | E4: =C4*D4 -> 0
E5: =C5*D5 -> 0
E6: =C6*D6 -> 0
E7: =C7*D7 -> 0
E8: =C8*D8 -> 0
B9: Ceiling | E9: =C9*D9 -> 0
E10: =C10*D10 -> 0
E11: =C11*D11 -> 0
E12: =C12*D12 -> 0
B13: Gables | E13: =(C13/2)*D13 -> 0
E14: =(C14/2)*D14 -> 0
E15: =C15*D15 -> 0 | F15: =SUM(E4:E15) -> 0

Sheet Performance & Payment Bonds
A1: Project Total
B3: =IF(B1<=100000,B1*0.0225,"") -> 0 | C3: =IF(AND(B1<=500000,B1>100000), ((B1-100000)*0.015)+2250,"") | D3: =IF(AND(B1<=2500000,B1>500000), ((B1-500000)*0.0105)+8250,"")
